pika.adapters.utils.connection_workflow|[INFO]|2025-03-12 04:42:27,742|Pika version 1.3.2 connecting to ('172.18.0.2', 5672)
pika.adapters.utils.io_services_utils|[INFO]|2025-03-12 04:42:27,743|Socket connected: <socket.socket fd=7, family=2, type=1, proto=6, laddr=('172.18.0.3', 46398), raddr=('172.18.0.2', 5672)>
pika.adapters.utils.connection_workflow|[INFO]|2025-03-12 04:42:27,743|Streaming transport linked up: (<pika.adapters.utils.io_services_utils._AsyncPlaintextTransport object at 0x72475f629b50>, _StreamingProtocolShim: <SelectConnection PROTOCOL transport=<pika.adapters.utils.io_services_utils._AsyncPlaintextTransport object at 0x72475f629b50> params=<ConnectionParameters host=rabbitmq port=5672 virtual_host=/ ssl=False>>).
pika.adapters.utils.io_services_utils|[INFO]|2025-03-12 04:42:27,751|Aborting transport connection: state=1; <socket.socket fd=7, family=2, type=1, proto=6, laddr=('172.18.0.3', 46398), raddr=('172.18.0.2', 5672)>
pika.adapters.utils.io_services_utils|[INFO]|2025-03-12 04:42:27,751|_AsyncTransportBase._initate_abort(): Initiating abrupt asynchronous transport shutdown: state=1; error=None; <socket.socket fd=7, family=2, type=1, proto=6, laddr=('172.18.0.3', 46398), raddr=('172.18.0.2', 5672)>
pika.adapters.utils.io_services_utils|[INFO]|2025-03-12 04:42:27,752|Deactivating transport: state=1; <socket.socket fd=7, family=2, type=1, proto=6, laddr=('172.18.0.3', 46398), raddr=('172.18.0.2', 5672)>
pika.connection|[INFO]|2025-03-12 04:42:27,752|AMQP stack terminated, failed to connect, or aborted: opened=False, error-arg=None; pending-error=ConnectionClosedByBroker: (403) 'ACCESS_REFUSED - Login was refused using authentication mechanism PLAIN. For details see the broker logfile.'
pika.connection|[ERROR]|2025-03-12 04:42:27,752|Connection closed while authenticating indicating a probable authentication error
pika.connection|[INFO]|2025-03-12 04:42:27,752|Connection setup terminated due to ProbableAuthenticationError: Client was disconnected at a connection stage indicating a probable authentication error: ("ConnectionClosedByBroker: (403) 'ACCESS_REFUSED - Login was refused using authentication mechanism PLAIN. For details see the broker logfile.'",)
pika.adapters.utils.connection_workflow|[ERROR]|2025-03-12 04:42:27,752|AMQPConnector - reporting failure: AMQPConnectorAMQPHandshakeError: ProbableAuthenticationError: Client was disconnected at a connection stage indicating a probable authentication error: ("ConnectionClosedByBroker: (403) 'ACCESS_REFUSED - Login was refused using authentication mechanism PLAIN. For details see the broker logfile.'",)
pika.adapters.utils.connection_workflow|[ERROR]|2025-03-12 04:42:27,753|AMQP connection workflow failed: AMQPConnectionWorkflowFailed: 1 exceptions in all; last exception - AMQPConnectorAMQPHandshakeError: ProbableAuthenticationError: Client was disconnected at a connection stage indicating a probable authentication error: ("ConnectionClosedByBroker: (403) 'ACCESS_REFUSED - Login was refused using authentication mechanism PLAIN. For details see the broker logfile.'",); first exception - None.
pika.adapters.utils.connection_workflow|[ERROR]|2025-03-12 04:42:27,753|AMQPConnectionWorkflow - reporting failure: AMQPConnectionWorkflowFailed: 1 exceptions in all; last exception - AMQPConnectorAMQPHandshakeError: ProbableAuthenticationError: Client was disconnected at a connection stage indicating a probable authentication error: ("ConnectionClosedByBroker: (403) 'ACCESS_REFUSED - Login was refused using authentication mechanism PLAIN. For details see the broker logfile.'",); first exception - None
pika.adapters.utils.io_services_utils|[INFO]|2025-03-12 04:42:27,753|Closing transport socket and unlinking: state=3; <socket.socket fd=7, family=2, type=1, proto=6, laddr=('172.18.0.3', 46398), raddr=('172.18.0.2', 5672)>
pika.adapters.blocking_connection|[ERROR]|2025-03-12 04:42:27,753|Connection workflow failed: AMQPConnectionWorkflowFailed: 1 exceptions in all; last exception - AMQPConnectorAMQPHandshakeError: ProbableAuthenticationError: Client was disconnected at a connection stage indicating a probable authentication error: ("ConnectionClosedByBroker: (403) 'ACCESS_REFUSED - Login was refused using authentication mechanism PLAIN. For details see the broker logfile.'",); first exception - None
pika.adapters.blocking_connection|[ERROR]|2025-03-12 04:42:27,753|Error in _create_connection().
Traceback (most recent call last):
  File "/usr/local/lib/python3.12/site-packages/pika/adapters/blocking_connection.py", line 451, in _create_connection
    raise self._reap_last_connection_workflow_error(error)
pika.exceptions.ProbableAuthenticationError: ConnectionClosedByBroker: (403) 'ACCESS_REFUSED - Login was refused using authentication mechanism PLAIN. For details see the broker logfile.'
